<?xml version="1.0"?>
<robot name="rpwr_arm">

  <material name="blue">
    <color rgba="0 0 0.8 0.7"/>
  </material>
  <material name="yellow">
    <color rgba="1 1 0 0.7"/>
  </material>
  <material name="black">
    <color rgba="0 0 0 0.7"/>
  </material>
  <material name="white">
    <color rgba="1 1 1 0.7"/>
  </material>

  <link name="base_link">
    <visual>
      <geometry>
        <cylinder length="0.01" radius="0.1"/>
      </geometry>
      <material name="yellow"/>
      <origin xyz="0.0 0.0 0.0"/>
    </visual>
  </link>

  <link name="link_0">
    <visual>
      <geometry>
        <box size="0.1 0.01 0.01"/>
      </geometry>
      <material name="blue"/>
      <origin xyz="0.05 0.0 0.0"/>
    </visual>
  </link>
    
  <joint name="link_0_joint" type="fixed">
    <origin rpy="0 -1.57079 0"  />
    <parent link="base_link"/>
    <child link="link_0"/>
  </joint>
    
  <link name="link_1">
    <visual>
      <geometry>
        <box size="0.25 0.01 0.01"/>
      </geometry>
      <material name="yellow"/>
      <origin xyz="0.125 0.0 0.0"/>
    </visual>
  </link>
    
  <joint name="link_1_joint" type="revolute">
    <axis xyz="0 0 1"/>
    <limit effort="1000.0" lower="-3.14159" upper="3.14159" velocity="0.5"/>
    <origin rpy="1.57079 1.57079 0" xyz="0.1 0.0 0.0" />
    <parent link="link_0"/>
    <child link="link_1"/>
  </joint>
    

  <!-- TODO: Implement link_2, link_2_joint, link_3, link_3_joint, ee_link, ee_joint-->
  

</robot>